Workbook
Name InterExter: Lista!$A$1:$A$3

Sheet Lista
A1: Externo | C1: Fora do prazo
A2: Interno | C2: Dentro do prazo
A3: Misto

Sheet TURNOVER GLOBAL-2025
A1: Insira aqui a sua logo! | C1: TURNOVER GLOBAL
F23: MOVIMENTAÇÕES
D24: MÊS | E24: TOTAL COLAB. | F24: ENTRADAS | G24: SAÍDAS | H24: TURNOVER (GLOBAL)
D25: DEZEMBRO | E25: 210
D26: JANEIRO | E26: 217 | F26: 7 | G26: 21 | H26: =((F26+G26)/2)/217 -> 0.064516129
D27: FEVEREIRO | E27: 210 | F27: 7 | G27: 10 | H27: =((F27+G27)/2)/E26 -> 0.039170507
D28: MARÇO | E28: 214 | F28: 14 | G28: 15 | H28: =((F28+G28)/2)/E27 -> 0.069047619
D29: ABRIL | E29: 207 | F29: 19 | G29: 12 | H29: =((F29+G29)/2)/E28 -> 0.072429907
D30: MAIO | E30: 204 | F30: 12 | G30: 7 | H30: =((F30+G30)/2)/E29 -> 0.04589372
D31: JUNHO | E31: 207 | F31: 9 | G31: 7 | H31: =((F31+G31)/2)/E30 -> 0.039215686
D32: JULHO | H32: =((F32+G32)/2)/E31 -> 0
D33: AGOSTO | H33: =((F33+G33)/2)/E32 -> #DIV/0!
D34: SETEMBRO | H34: =((F34+G34)/2)/E33 -> #DIV/0!
D35: OUTUBRO | H35: =((F35+G35)/2)/E34 -> #DIV/0!
D36: NOVEMBRO | H36: =((F36+G36)/2)/E35 -> #DIV/0!
D37: DEZEMBRO | H37: =((F37+G37)/2)/E36 -> #DIV/0!
G38: TOTAL | H38: =SUM(H26:H37) -> #DIV/0!
F42: MOVIMENTAÇÕES - LUBE
D43: MÊS | E43: TOTAL COLAB. | F43: ENTRADAS | G43: SAÍDAS | H43: TURNOVER (GLOBAL)
D44: DEZEMBRO | E44: ='LUBE ES'!E25 -> 0 | F44: ='LUBE ES'!F25 -> 0 | G44: ='LUBE ES'!G25 -> 0 | H44: ='LUBE ES'!H25 -> 0
D45: JANEIRO | E45: ='LUBE ES'!E26 -> 109 | F45: ='LUBE ES'!F26 -> 3 | G45: ='LUBE ES'!G26 -> 3 | H45: ='LUBE ES'!H26 -> 0.027522936
D46: FEVEREIRO | E46: ='LUBE ES'!E27 -> 110 | F46: ='LUBE ES'!F27 -> 2 | G46: ='LUBE ES'!G27 -> 3 | H46: ='LUBE ES'!H27 -> 0.022727273
D47: MARÇO | E47: ='LUBE ES'!E28 -> 104 | F47: ='LUBE ES'!F28 -> 1 | G47: ='LUBE ES'!G28 -> 9 | H47: ='LUBE ES'!H28 -> 0.048076923
D48: ABRIL | E48: ='LUBE ES'!E29 -> 112 | F48: ='LUBE ES'!F29 -> 7 | G48: ='LUBE ES'!G29 -> 6 | H48: ='LUBE ES'!H29 -> 0.058035714
D49: MAIO | E49: ='LUBE ES'!E30 -> 115 | F49: ='LUBE ES'!F30 -> 5 | G49: ='LUBE ES'!G30 -> 3 | H49: ='LUBE ES'!H30 -> 0.034782609
D50: JUNHO | E50: ='LUBE ES'!E31 -> 114 | F50: ='LUBE ES'!F31 -> 4 | G50: ='LUBE ES'!G31 -> 4 | H50: ='LUBE ES'!H31 -> 0.035087719
D51: JULHO | E51: ='LUBE ES'!E32 -> 109 | F51: ='LUBE ES'!F32 -> 3 | G51: ='LUBE ES'!G32 -> 7 | H51: ='LUBE ES'!H32 -> 0.04587156
D52: AGOSTO | E52: ='LUBE ES'!E33 -> 113 | F52: ='LUBE ES'!F33 -> 7 | G52: ='LUBE ES'!G33 -> 8 | H52: ='LUBE ES'!H33 -> 0.066371681
D53: SETEMBRO | E53: ='LUBE ES'!E34 -> 0 | F53: ='LUBE ES'!F34 -> 0 | G53: ='LUBE ES'!G34 -> 0 | H53: ='LUBE ES'!H34 -> #DIV/0!
D54: OUTUBRO | E54: ='LUBE ES'!E35 -> 0 | F54: ='LUBE ES'!F35 -> 0 | G54: ='LUBE ES'!G35 -> 0 | H54: ='LUBE ES'!H35 -> #DIV/0!
D55: NOVEMBRO | E55: ='LUBE ES'!E36 -> 0 | F55: ='LUBE ES'!F36 -> 0 | G55: ='LUBE ES'!G36 -> 0 | H55: ='LUBE ES'!H36 -> #DIV/0!
D56: DEZEMBRO | E56: ='LUBE ES'!E37 -> 0 | F56: ='LUBE ES'!F37 -> 0 | G56: ='LUBE ES'!G37 -> 0 | H56: ='LUBE ES'!H37 -> #DIV/0!
G57: TOTAL | H57: =SUM(H45:H56) -> #DIV/0!
F61: MOVIMENTAÇÕES - LUBE RJ
D62: MÊS | E62: TOTAL COLAB. | F62: ENTRADAS | G62: SAÍDAS | H62: TURNOVER (GLOBAL)
D63: JANEIRO | E63: ='LUBE RJ'!E25 -> 0 | F63: ='LUBE RJ'!F25 -> 0 | G63: ='LUBE RJ'!G25 -> 0 | H63: ='LUBE RJ'!H25 -> 0
D64: FEVEREIRO | E64: ='LUBE RJ'!E26 -> 0 | F64: ='LUBE RJ'!F26 -> 0 | G64: ='LUBE RJ'!G26 -> 0 | H64: ='LUBE RJ'!H26 -> #DIV/0!
D65: MARÇO | E65: ='LUBE RJ'!E27 -> 1 | F65: ='LUBE RJ'!F27 -> 1 | G65: ='LUBE RJ'!G27 -> 0 | H65: ='LUBE RJ'!H27 -> 0.5
D66: ABRIL | E66: ='LUBE RJ'!E28 -> 10 | F66: ='LUBE RJ'!F28 -> 9 | G66: ='LUBE RJ'!G28 -> 0 | H66: ='LUBE RJ'!H28 -> 0.45
D67: MAIO | E67: ='LUBE RJ'!E29 -> 10 | F67: ='LUBE RJ'!F29 -> 0 | G67: ='LUBE RJ'!G29 -> 0 | H67: ='LUBE RJ'!H29 -> 0
...

Sheet LUBE ES
A1: Insira aqui a sua logo! | C1: TURNOVER GLOBAL
F23: MOVIMENTAÇÕES
D24: MÊS | E24: TOTAL COLAB. | F24: ENTRADAS | G24: SAÍDAS | H24: TURNOVER (GLOBAL)
D25: DEZEMBRO | E25: 0
D26: JANEIRO | E26: 109 | F26: 3 | G26: 3 | H26: =((F26+G26)/2)/E26 -> 0.027522936
D27: FEVEREIRO | E27: 110 | F27: 2 | G27: 3 | H27: =((F27+G27)/2)/E27 -> 0.022727273
D28: MARÇO | E28: 104 | F28: 1 | G28: 9 | H28: =((F28+G28)/2)/E28 -> 0.048076923
D29: ABRIL | E29: 112 | F29: 7 | G29: 6 | H29: =((F29+G29)/2)/E29 -> 0.058035714
D30: MAIO | E30: 115 | F30: 5 | G30: 3 | H30: =((F30+G30)/2)/E30 -> 0.034782609
D31: JUNHO | E31: 114 | F31: 4 | G31: 4 | H31: =((F31+G31)/2)/E31 -> 0.035087719
D32: JULHO | E32: 109 | F32: 3 | G32: 7 | H32: =((F32+G32)/2)/E32 -> 0.04587156
D33: AGOSTO | E33: 113 | F33: 7 | G33: 8 | H33: =((F33+G33)/2)/E33 -> 0.066371681
D34: SETEMBRO | H34: =((F34+G34)/2)/E34 -> #DIV/0!
D35: OUTUBRO | H35: =((F35+G35)/2)/E35 -> #DIV/0!
D36: NOVEMBRO | H36: =((F36+G36)/2)/E36 -> #DIV/0!
D37: DEZEMBRO | H37: =((F37+G37)/2)/E37 -> #DIV/0!
G38: TOTAL | H38: =SUM(H26:H37) -> #DIV/0!

Sheet LUBE RJ
A1: Insira aqui a sua logo! | C1: TURNOVER GLOBAL
F23: MOVIMENTAÇÕES
D24: MÊS | E24: TOTAL COLAB. | F24: ENTRADAS | G24: SAÍDAS | H24: TURNOVER (GLOBAL)
D25: DEZEMBRO | E25: 0
D26: JANEIRO | E26: 0 | F26: 0 | G26: 0 | H26: =((F26+G26)/2)/E26 -> #DIV/0!
D27: FEVEREIRO | E27: 1 | F27: 1 | G27: 0 | H27: =((F27+G27)/2)/E27 -> 0.5
D28: MARÇO | E28: 10 | F28: 9 | G28: 0 | H28: =((F28+G28)/2)/E28 -> 0.45
D29: ABRIL | E29: 10 | F29: 0 | G29: 0 | H29: =((F29+G29)/2)/E29 -> 0
D30: MAIO | E30: 10 | F30: 0 | G30: 0 | H30: =((F30+G30)/2)/E30 -> 0
D31: JUNHO | E31: 10 | F31: 0 | G31: 0 | H31: =((F31+G31)/2)/E31 -> 0
D32: JULHO | E32: 11 | F32: 1 | G32: 0 | H32: =((F32+G32)/2)/E32 -> 0.045454545
D33: AGOSTO | E33: 12 | F33: 1 | G33: 0 | H33: =((F33+G33)/2)/E33 -> 0.041666667
D34: SETEMBRO | H34: =((F34+G34)/2)/E34 -> #DIV/0!
D35: OUTUBRO | H35: =((F35+G35)/2)/E35 -> #DIV/0!
D36: NOVEMBRO | H36: =((F36+G36)/2)/E36 -> #DIV/0!
D37: DEZEMBRO | H37: =((F37+G37)/2)/E37 -> #DIV/0!
G38: TOTAL | H38: =SUM(H26:H37) -> #DIV/0!

Sheet LLOG
A1: Insira aqui a sua logo! | C1: TURNOVER GLOBAL
F23: MOVIMENTAÇÕES
D24: MÊS | E24: TOTAL COLAB. | F24: ENTRADAS | G24: SAÍDAS | H24: TURNOVER (GLOBAL)
D25: DEZEMBRO | E25: 77
D26: JANEIRO | E26: 75 | F26: 3 | G26: 3 | H26: =((F26+G26)/2)/216 -> 0.013888889
D27: FEVEREIRO | E27: 76 | F27: 5 | G27: 4 | H27: =((F27+G27)/2)/E26 -> 0.06
D28: MARÇO | E28: 73 | F28: 2 | G28: 5 | H28: =((F28+G28)/2)/E27 -> 0.046052632
D29: ABRIL | E29: 70 | F29: 1 | G29: 4 | H29: =((F29+G29)/2)/E28 -> 0.034246575
D30: MAIO | E30: 68 | F30: 5 | G30: 3 | H30: =((F30+G30)/2)/E29 -> 0.057142857
D31: JUNHO | E31: 68 | F31: 5 | G31: 3 | H31: =((F31+G31)/2)/E30 -> 0.058823529
D32: JULHO | E32: 68 | F32: 5 | G32: 5 | H32: =((F32+G32)/2)/E31 -> 0.073529412
D33: AGOSTO | E33: 69 | F33: 6 | G33: 5 | H33: =((F33+G33)/2)/E32 -> 0.080882353
D34: SETEMBRO | H34: =((F34+G34)/2)/E33 -> 0
D35: OUTUBRO | H35: =((F35+G35)/2)/E34 -> #DIV/0!
D36: NOVEMBRO | H36: =((F36+G36)/2)/E35 -> #DIV/0!
D37: DEZEMBRO | H37: =((F37+G37)/2)/E36 -> #DIV/0!
G38: TOTAL | H38: =SUM(H26:H37) -> #DIV/0!

Sheet IMPERIO 
A1: Insira aqui a sua logo! | C1: TURNOVER GLOBAL
F23: MOVIMENTAÇÕES
D24: MÊS | E24: TOTAL COLAB. | F24: ENTRADAS | G24: SAÍDAS | H24: TURNOVER (GLOBAL)
D25: DEZEMBRO | E25: 76
D26: JANEIRO | E26: 22 | F26: 1 | G26: 15 | H26: =((F26+G26)/2)/216 -> 0.037037037
D27: FEVEREIRO | E27: 8 | F27: 0 | G27: 3 | H27: =((F27+G27)/2)/E26 -> 0.068181818
D28: MARÇO | E28: 6 | F28: 0 | G28: 1 | H28: =((F28+G28)/2)/E27 -> 0.0625
D29: ABRIL | E29: 5 | F29: 0 | G29: 1 | H29: =((F29+G29)/2)/E28 -> 0.083333333
D30: MAIO | E30: 5 | F30: 1 | G30: 0 | H30: =((F30+G30)/2)/E29 -> 0.1
D31: JUNHO | E31: 5 | F31: 0 | G31: 0 | H31: =((F31+G31)/2)/E30 -> 0
D32: JULHO | E32: 5 | F32: 0 | G32: 0 | H32: =((F32+G32)/2)/E31 -> 0
D33: AGOSTO | E33: 5 | F33: 0 | G33: 0 | H33: =((F33+G33)/2)/E32 -> 0
D34: SETEMBRO | H34: =((F34+G34)/2)/E33 -> 0
D35: OUTUBRO | H35: =((F35+G35)/2)/E34 -> #DIV/0!
D36: NOVEMBRO | H36: =((F36+G36)/2)/E35 -> #DIV/0!
D37: DEZEMBRO | H37: =((F37+G37)/2)/E36 -> #DIV/0!
G38: TOTAL | H38: =SUM(H26:H37) -> #DIV/0!

Sheet SERMAR
A1: Insira aqui a sua logo! | C1: TURNOVER GLOBAL
F23: MOVIMENTAÇÕES
D24: MÊS | E24: TOTAL COLAB. | F24: ENTRADAS | G24: SAÍDAS | H24: TURNOVER (GLOBAL)
D25: DEZEMBRO | E25: 7
D26: JANEIRO | E26: 7 | F26: 0 | G26: 0 | H26: =((F26+G26)/2)/216 -> 0
D27: FEVEREIRO | E27: 7 | F27: 0 | G27: 0 | H27: =((F27+G27)/2)/E26 -> 0
D28: MARÇO | E28: 7 | F28: 0 | G28: 0 | H28: =((F28+G28)/2)/E27 -> 0
D29: ABRIL | E29: 7 | F29: 0 | G29: 1 | H29: =((F29+G29)/2)/E28 -> 0.071428571
D30: MAIO | E30: 6 | F30: 0 | G30: 1 | H30: =((F30+G30)/2)/E29 -> 0.071428571
D31: JUNHO | E31: 5 | F31: 0 | G31: 0 | H31: =((F31+G31)/2)/E30 -> 0
D32: JULHO | E32: 5 | F32: 0 | G32: 0 | H32: =((F32+G32)/2)/E31 -> 0
D33: AGOSTO | E33: 5 | F33: 0 | G33: 0 | H33: =((F33+G33)/2)/E32 -> 0
D34: SETEMBRO | H34: =((F34+G34)/2)/E33 -> 0
D35: OUTUBRO | H35: =((F35+G35)/2)/E34 -> #DIV/0!
D36: NOVEMBRO | H36: =((F36+G36)/2)/E35 -> #DIV/0!
D37: DEZEMBRO | H37: =((F37+G37)/2)/E36 -> #DIV/0!
G38: TOTAL | H38: =SUM(H26:H37) -> #DIV/0!
